WARNING :- 2023-04-04 17:43:13,620 - app : Starting the db connection to update the details 
INFO :- 2023-04-04 17:43:13,841 - app : Member details updated: {'username': 'Anjali'}
INFO :- 2023-04-04 17:43:13,841 - app : Member details updated: {'username': 'Anjali'}
WARNING :- 2023-04-04 17:43:13,842 - app : Hence member details updated, closing the connection
WARNING :- 2023-04-04 17:43:13,842 - app : Hence member details updated, closing the connection
WARNING :- 2023-04-04 17:43:13,842 - app : Hence member details updated, closing the connection
WARNING :- 2023-04-04 17:43:42,392 - app : Starting the db connection to update the details 
WARNING :- 2023-04-04 17:43:42,392 - app : Starting the db connection to update the details 
WARNING :- 2023-04-04 17:43:42,392 - app : Starting the db connection to update the details 
WARNING :- 2023-04-04 17:43:42,392 - app : Starting the db connection to update the details 
INFO :- 2023-04-04 17:43:42,712 - app : Member details updated: {'username': 'Kabir'}
INFO :- 2023-04-04 17:43:42,712 - app : Member details updated: {'username': 'Kabir'}
INFO :- 2023-04-04 17:43:42,712 - app : Member details updated: {'username': 'Kabir'}
INFO :- 2023-04-04 17:43:42,712 - app : Member details updated: {'username': 'Kabir'}
INFO :- 2023-04-04 17:43:42,712 - app : Member details updated: {'username': 'Kabir'}
WARNING :- 2023-04-04 17:43:42,713 - app : Hence member details updated, closing the connection
WARNING :- 2023-04-04 17:43:42,713 - app : Hence member details updated, closing the connection
WARNING :- 2023-04-04 17:43:42,713 - app : Hence member details updated, closing the connection
WARNING :- 2023-04-04 17:43:42,713 - app : Hence member details updated, closing the connection
WARNING :- 2023-04-04 17:43:42,713 - app : Hence member details updated, closing the connection
WARNING :- 2023-04-04 17:43:42,713 - app : Hence member details updated, closing the connection
WARNING :- 2023-04-04 17:47:35,982 - app : Starting the db connection to display items in the cart
WARNING :- 2023-04-04 17:47:35,982 - app : Starting the db connection to display items in the cart
WARNING :- 2023-04-04 17:47:35,982 - app : Starting the db connection to display items in the cart
WARNING :- 2023-04-04 17:47:35,982 - app : Starting the db connection to display items in the cart
WARNING :- 2023-04-04 17:47:35,982 - app : Starting the db connection to display items in the cart
WARNING :- 2023-04-04 17:47:35,982 - app : Starting the db connection to display items in the cart
WARNING :- 2023-04-04 17:47:35,982 - app : Starting the db connection to display items in the cart
ERROR :- 2023-04-04 17:47:36,287 - app : Error occurred: invalid input syntax for type boolean: "1992-03-17"
LINE 2: ...d) VALUES ('Encyclopedia', 'Kabir', '1990-12-23', '1992-03-1...
                                                             ^
Traceback (most recent call last):
  File "/home/bc2113451/Desktop/VS Code/Oops/Library/app.py", line 40, in add_member
    cur.execute(add_query, values)
psycopg2.errors.InvalidTextRepresentation: invalid input syntax for type boolean: "1992-03-17"
LINE 2: ...d) VALUES ('Encyclopedia', 'Kabir', '1990-12-23', '1992-03-1...
                                                             ^

ERROR :- 2023-04-04 17:47:36,287 - app : Error occurred: invalid input syntax for type boolean: "1992-03-17"
LINE 2: ...d) VALUES ('Encyclopedia', 'Kabir', '1990-12-23', '1992-03-1...
                                                             ^
Traceback (most recent call last):
  File "/home/bc2113451/Desktop/VS Code/Oops/Library/app.py", line 40, in add_member
    cur.execute(add_query, values)
psycopg2.errors.InvalidTextRepresentation: invalid input syntax for type boolean: "1992-03-17"
LINE 2: ...d) VALUES ('Encyclopedia', 'Kabir', '1990-12-23', '1992-03-1...
                                                             ^

ERROR :- 2023-04-04 17:47:36,287 - app : Error occurred: invalid input syntax for type boolean: "1992-03-17"
LINE 2: ...d) VALUES ('Encyclopedia', 'Kabir', '1990-12-23', '1992-03-1...
                                                             ^
Traceback (most recent call last):
  File "/home/bc2113451/Desktop/VS Code/Oops/Library/app.py", line 40, in add_member
    cur.execute(add_query, values)
psycopg2.errors.InvalidTextRepresentation: invalid input syntax for type boolean: "1992-03-17"
LINE 2: ...d) VALUES ('Encyclopedia', 'Kabir', '1990-12-23', '1992-03-1...
                                                             ^

ERROR :- 2023-04-04 17:47:36,287 - app : Error occurred: invalid input syntax for type boolean: "1992-03-17"
LINE 2: ...d) VALUES ('Encyclopedia', 'Kabir', '1990-12-23', '1992-03-1...
                                                             ^
Traceback (most recent call last):
  File "/home/bc2113451/Desktop/VS Code/Oops/Library/app.py", line 40, in add_member
    cur.execute(add_query, values)
psycopg2.errors.InvalidTextRepresentation: invalid input syntax for type boolean: "1992-03-17"
LINE 2: ...d) VALUES ('Encyclopedia', 'Kabir', '1990-12-23', '1992-03-1...
                                                             ^

ERROR :- 2023-04-04 17:47:36,287 - app : Error occurred: invalid input syntax for type boolean: "1992-03-17"
LINE 2: ...d) VALUES ('Encyclopedia', 'Kabir', '1990-12-23', '1992-03-1...
                                                             ^
Traceback (most recent call last):
  File "/home/bc2113451/Desktop/VS Code/Oops/Library/app.py", line 40, in add_member
    cur.execute(add_query, values)
psycopg2.errors.InvalidTextRepresentation: invalid input syntax for type boolean: "1992-03-17"
LINE 2: ...d) VALUES ('Encyclopedia', 'Kabir', '1990-12-23', '1992-03-1...
                                                             ^

ERROR :- 2023-04-04 17:47:36,287 - app : Error occurred: invalid input syntax for type boolean: "1992-03-17"
LINE 2: ...d) VALUES ('Encyclopedia', 'Kabir', '1990-12-23', '1992-03-1...
                                                             ^
Traceback (most recent call last):
  File "/home/bc2113451/Desktop/VS Code/Oops/Library/app.py", line 40, in add_member
    cur.execute(add_query, values)
psycopg2.errors.InvalidTextRepresentation: invalid input syntax for type boolean: "1992-03-17"
LINE 2: ...d) VALUES ('Encyclopedia', 'Kabir', '1990-12-23', '1992-03-1...
                                                             ^

ERROR :- 2023-04-04 17:47:36,287 - app : Error occurred: invalid input syntax for type boolean: "1992-03-17"
LINE 2: ...d) VALUES ('Encyclopedia', 'Kabir', '1990-12-23', '1992-03-1...
                                                             ^
Traceback (most recent call last):
  File "/home/bc2113451/Desktop/VS Code/Oops/Library/app.py", line 40, in add_member
    cur.execute(add_query, values)
psycopg2.errors.InvalidTextRepresentation: invalid input syntax for type boolean: "1992-03-17"
LINE 2: ...d) VALUES ('Encyclopedia', 'Kabir', '1990-12-23', '1992-03-1...
                                                             ^

ERROR :- 2023-04-04 17:47:36,287 - app : Error occurred: invalid input syntax for type boolean: "1992-03-17"
LINE 2: ...d) VALUES ('Encyclopedia', 'Kabir', '1990-12-23', '1992-03-1...
                                                             ^
Traceback (most recent call last):
  File "/home/bc2113451/Desktop/VS Code/Oops/Library/app.py", line 40, in add_member
    cur.execute(add_query, values)
psycopg2.errors.InvalidTextRepresentation: invalid input syntax for type boolean: "1992-03-17"
LINE 2: ...d) VALUES ('Encyclopedia', 'Kabir', '1990-12-23', '1992-03-1...
                                                             ^

WARNING :- 2023-04-04 17:47:36,288 - app : Hence member added, closing the connection
WARNING :- 2023-04-04 17:47:36,288 - app : Hence member added, closing the connection
WARNING :- 2023-04-04 17:47:36,288 - app : Hence member added, closing the connection
WARNING :- 2023-04-04 17:47:36,288 - app : Hence member added, closing the connection
WARNING :- 2023-04-04 17:47:36,288 - app : Hence member added, closing the connection
WARNING :- 2023-04-04 17:47:36,288 - app : Hence member added, closing the connection
WARNING :- 2023-04-04 17:47:36,288 - app : Hence member added, closing the connection
WARNING :- 2023-04-04 17:47:36,288 - app : Hence member added, closing the connection
WARNING :- 2023-04-04 17:47:36,288 - app : Hence member added, closing the connection
ERROR :- 2023-04-04 17:47:36,289 - app : Exception on /register [POST]
Traceback (most recent call last):
  File "/home/bc2113451/Desktop/VS Code/Oops/Library/app.py", line 40, in add_member
    cur.execute(add_query, values)
psycopg2.errors.InvalidTextRepresentation: invalid input syntax for type boolean: "1992-03-17"
LINE 2: ...d) VALUES ('Encyclopedia', 'Kabir', '1990-12-23', '1992-03-1...
                                                             ^


During handling of the above exception, another exception occurred:

Traceback (most recent call last):
  File "/home/bc2113451/Desktop/VS Code/Oops/.venv/lib/python3.8/site-packages/flask/app.py", line 2528, in wsgi_app
    response = self.full_dispatch_request()
  File "/home/bc2113451/Desktop/VS Code/Oops/.venv/lib/python3.8/site-packages/flask/app.py", line 1825, in full_dispatch_request
    rv = self.handle_user_exception(e)
  File "/home/bc2113451/Desktop/VS Code/Oops/.venv/lib/python3.8/site-packages/flask/app.py", line 1823, in full_dispatch_request
    rv = self.dispatch_request()
  File "/home/bc2113451/Desktop/VS Code/Oops/.venv/lib/python3.8/site-packages/flask/app.py", line 1799, in dispatch_request
    return self.ensure_sync(self.view_functions[rule.endpoint])(**view_args)
  File "/home/bc2113451/Desktop/VS Code/Oops/Library/app.py", line 48, in add_member
    return jsonify({"message": error})
  File "/home/bc2113451/Desktop/VS Code/Oops/.venv/lib/python3.8/site-packages/flask/json/__init__.py", line 342, in jsonify
    return current_app.json.response(*args, **kwargs)
  File "/home/bc2113451/Desktop/VS Code/Oops/.venv/lib/python3.8/site-packages/flask/json/provider.py", line 309, in response
    f"{self.dumps(obj, **dump_args)}\n", mimetype=mimetype
  File "/home/bc2113451/Desktop/VS Code/Oops/.venv/lib/python3.8/site-packages/flask/json/provider.py", line 230, in dumps
    return json.dumps(obj, **kwargs)
  File "/usr/lib/python3.8/json/__init__.py", line 234, in dumps
    return cls(
  File "/usr/lib/python3.8/json/encoder.py", line 199, in encode
    chunks = self.iterencode(o, _one_shot=True)
  File "/usr/lib/python3.8/json/encoder.py", line 257, in iterencode
    return _iterencode(o, 0)
  File "/home/bc2113451/Desktop/VS Code/Oops/.venv/lib/python3.8/site-packages/flask/json/provider.py", line 122, in _default
    raise TypeError(f"Object of type {type(o).__name__} is not JSON serializable")
TypeError: Object of type InvalidTextRepresentation is not JSON serializable
ERROR :- 2023-04-04 17:47:36,289 - app : Exception on /register [POST]
Traceback (most recent call last):
  File "/home/bc2113451/Desktop/VS Code/Oops/Library/app.py", line 40, in add_member
    cur.execute(add_query, values)
psycopg2.errors.InvalidTextRepresentation: invalid input syntax for type boolean: "1992-03-17"
LINE 2: ...d) VALUES ('Encyclopedia', 'Kabir', '1990-12-23', '1992-03-1...
                                                             ^


During handling of the above exception, another exception occurred:

Traceback (most recent call last):
  File "/home/bc2113451/Desktop/VS Code/Oops/.venv/lib/python3.8/site-packages/flask/app.py", line 2528, in wsgi_app
    response = self.full_dispatch_request()
  File "/home/bc2113451/Desktop/VS Code/Oops/.venv/lib/python3.8/site-packages/flask/app.py", line 1825, in full_dispatch_request
    rv = self.handle_user_exception(e)
  File "/home/bc2113451/Desktop/VS Code/Oops/.venv/lib/python3.8/site-packages/flask/app.py", line 1823, in full_dispatch_request
    rv = self.dispatch_request()
  File "/home/bc2113451/Desktop/VS Code/Oops/.venv/lib/python3.8/site-packages/flask/app.py", line 1799, in dispatch_request
    return self.ensure_sync(self.view_functions[rule.endpoint])(**view_args)
  File "/home/bc2113451/Desktop/VS Code/Oops/Library/app.py", line 48, in add_member
    return jsonify({"message": error})
  File "/home/bc2113451/Desktop/VS Code/Oops/.venv/lib/python3.8/site-packages/flask/json/__init__.py", line 342, in jsonify
    return current_app.json.response(*args, **kwargs)
  File "/home/bc2113451/Desktop/VS Code/Oops/.venv/lib/python3.8/site-packages/flask/json/provider.py", line 309, in response
    f"{self.dumps(obj, **dump_args)}\n", mimetype=mimetype
  File "/home/bc2113451/Desktop/VS Code/Oops/.venv/lib/python3.8/site-packages/flask/json/provider.py", line 230, in dumps
    return json.dumps(obj, **kwargs)
  File "/usr/lib/python3.8/json/__init__.py", line 234, in dumps
    return cls(
  File "/usr/lib/python3.8/json/encoder.py", line 199, in encode
    chunks = self.iterencode(o, _one_shot=True)
  File "/usr/lib/python3.8/json/encoder.py", line 257, in iterencode
    return _iterencode(o, 0)
  File "/home/bc2113451/Desktop/VS Code/Oops/.venv/lib/python3.8/site-packages/flask/json/provider.py", line 122, in _default
    raise TypeError(f"Object of type {type(o).__name__} is not JSON serializable")
TypeError: Object of type InvalidTextRepresentation is not JSON serializable
ERROR :- 2023-04-04 17:47:36,289 - app : Exception on /register [POST]
Traceback (most recent call last):
  File "/home/bc2113451/Desktop/VS Code/Oops/Library/app.py", line 40, in add_member
    cur.execute(add_query, values)
psycopg2.errors.InvalidTextRepresentation: invalid input syntax for type boolean: "1992-03-17"
LINE 2: ...d) VALUES ('Encyclopedia', 'Kabir', '1990-12-23', '1992-03-1...
                                                             ^


During handling of the above exception, another exception occurred:

Traceback (most recent call last):
  File "/home/bc2113451/Desktop/VS Code/Oops/.venv/lib/python3.8/site-packages/flask/app.py", line 2528, in wsgi_app
    response = self.full_dispatch_request()
  File "/home/bc2113451/Desktop/VS Code/Oops/.venv/lib/python3.8/site-packages/flask/app.py", line 1825, in full_dispatch_request
    rv = self.handle_user_exception(e)
  File "/home/bc2113451/Desktop/VS Code/Oops/.venv/lib/python3.8/site-packages/flask/app.py", line 1823, in full_dispatch_request
    rv = self.dispatch_request()
  File "/home/bc2113451/Desktop/VS Code/Oops/.venv/lib/python3.8/site-packages/flask/app.py", line 1799, in dispatch_request
    return self.ensure_sync(self.view_functions[rule.endpoint])(**view_args)
  File "/home/bc2113451/Desktop/VS Code/Oops/Library/app.py", line 48, in add_member
    return jsonify({"message": error})
  File "/home/bc2113451/Desktop/VS Code/Oops/.venv/lib/python3.8/site-packages/flask/json/__init__.py", line 342, in jsonify
    return current_app.json.response(*args, **kwargs)
  File "/home/bc2113451/Desktop/VS Code/Oops/.venv/lib/python3.8/site-packages/flask/json/provider.py", line 309, in response
    f"{self.dumps(obj, **dump_args)}\n", mimetype=mimetype
  File "/home/bc2113451/Desktop/VS Code/Oops/.venv/lib/python3.8/site-packages/flask/json/provider.py", line 230, in dumps
    return json.dumps(obj, **kwargs)
  File "/usr/lib/python3.8/json/__init__.py", line 234, in dumps
    return cls(
  File "/usr/lib/python3.8/json/encoder.py", line 199, in encode
    chunks = self.iterencode(o, _one_shot=True)
  File "/usr/lib/python3.8/json/encoder.py", line 257, in iterencode
    return _iterencode(o, 0)
  File "/home/bc2113451/Desktop/VS Code/Oops/.venv/lib/python3.8/site-packages/flask/json/provider.py", line 122, in _default
    raise TypeError(f"Object of type {type(o).__name__} is not JSON serializable")
TypeError: Object of type InvalidTextRepresentation is not JSON serializable
ERROR :- 2023-04-04 17:47:36,289 - app : Exception on /register [POST]
Traceback (most recent call last):
  File "/home/bc2113451/Desktop/VS Code/Oops/Library/app.py", line 40, in add_member
    cur.execute(add_query, values)
psycopg2.errors.InvalidTextRepresentation: invalid input syntax for type boolean: "1992-03-17"
LINE 2: ...d) VALUES ('Encyclopedia', 'Kabir', '1990-12-23', '1992-03-1...
                                                             ^


During handling of the above exception, another exception occurred:

Traceback (most recent call last):
  File "/home/bc2113451/Desktop/VS Code/Oops/.venv/lib/python3.8/site-packages/flask/app.py", line 2528, in wsgi_app
    response = self.full_dispatch_request()
  File "/home/bc2113451/Desktop/VS Code/Oops/.venv/lib/python3.8/site-packages/flask/app.py", line 1825, in full_dispatch_request
    rv = self.handle_user_exception(e)
  File "/home/bc2113451/Desktop/VS Code/Oops/.venv/lib/python3.8/site-packages/flask/app.py", line 1823, in full_dispatch_request
    rv = self.dispatch_request()
  File "/home/bc2113451/Desktop/VS Code/Oops/.venv/lib/python3.8/site-packages/flask/app.py", line 1799, in dispatch_request
    return self.ensure_sync(self.view_functions[rule.endpoint])(**view_args)
  File "/home/bc2113451/Desktop/VS Code/Oops/Library/app.py", line 48, in add_member
    return jsonify({"message": error})
  File "/home/bc2113451/Desktop/VS Code/Oops/.venv/lib/python3.8/site-packages/flask/json/__init__.py", line 342, in jsonify
    return current_app.json.response(*args, **kwargs)
  File "/home/bc2113451/Desktop/VS Code/Oops/.venv/lib/python3.8/site-packages/flask/json/provider.py", line 309, in response
    f"{self.dumps(obj, **dump_args)}\n", mimetype=mimetype
  File "/home/bc2113451/Desktop/VS Code/Oops/.venv/lib/python3.8/site-packages/flask/json/provider.py", line 230, in dumps
    return json.dumps(obj, **kwargs)
  File "/usr/lib/python3.8/json/__init__.py", line 234, in dumps
    return cls(
  File "/usr/lib/python3.8/json/encoder.py", line 199, in encode
    chunks = self.iterencode(o, _one_shot=True)
  File "/usr/lib/python3.8/json/encoder.py", line 257, in iterencode
    return _iterencode(o, 0)
  File "/home/bc2113451/Desktop/VS Code/Oops/.venv/lib/python3.8/site-packages/flask/json/provider.py", line 122, in _default
    raise TypeError(f"Object of type {type(o).__name__} is not JSON serializable")
TypeError: Object of type InvalidTextRepresentation is not JSON serializable
ERROR :- 2023-04-04 17:47:36,289 - app : Exception on /register [POST]
Traceback (most recent call last):
  File "/home/bc2113451/Desktop/VS Code/Oops/Library/app.py", line 40, in add_member
    cur.execute(add_query, values)
psycopg2.errors.InvalidTextRepresentation: invalid input syntax for type boolean: "1992-03-17"
LINE 2: ...d) VALUES ('Encyclopedia', 'Kabir', '1990-12-23', '1992-03-1...
                                                             ^


During handling of the above exception, another exception occurred:

Traceback (most recent call last):
  File "/home/bc2113451/Desktop/VS Code/Oops/.venv/lib/python3.8/site-packages/flask/app.py", line 2528, in wsgi_app
    response = self.full_dispatch_request()
  File "/home/bc2113451/Desktop/VS Code/Oops/.venv/lib/python3.8/site-packages/flask/app.py", line 1825, in full_dispatch_request
    rv = self.handle_user_exception(e)
  File "/home/bc2113451/Desktop/VS Code/Oops/.venv/lib/python3.8/site-packages/flask/app.py", line 1823, in full_dispatch_request
    rv = self.dispatch_request()
  File "/home/bc2113451/Desktop/VS Code/Oops/.venv/lib/python3.8/site-packages/flask/app.py", line 1799, in dispatch_request
    return self.ensure_sync(self.view_functions[rule.endpoint])(**view_args)
  File "/home/bc2113451/Desktop/VS Code/Oops/Library/app.py", line 48, in add_member
    return jsonify({"message": error})
  File "/home/bc2113451/Desktop/VS Code/Oops/.venv/lib/python3.8/site-packages/flask/json/__init__.py", line 342, in jsonify
    return current_app.json.response(*args, **kwargs)
  File "/home/bc2113451/Desktop/VS Code/Oops/.venv/lib/python3.8/site-packages/flask/json/provider.py", line 309, in response
    f"{self.dumps(obj, **dump_args)}\n", mimetype=mimetype
  File "/home/bc2113451/Desktop/VS Code/Oops/.venv/lib/python3.8/site-packages/flask/json/provider.py", line 230, in dumps
    return json.dumps(obj, **kwargs)
  File "/usr/lib/python3.8/json/__init__.py", line 234, in dumps
    return cls(
  File "/usr/lib/python3.8/json/encoder.py", line 199, in encode
    chunks = self.iterencode(o, _one_shot=True)
  File "/usr/lib/python3.8/json/encoder.py", line 257, in iterencode
    return _iterencode(o, 0)
  File "/home/bc2113451/Desktop/VS Code/Oops/.venv/lib/python3.8/site-packages/flask/json/provider.py", line 122, in _default
    raise TypeError(f"Object of type {type(o).__name__} is not JSON serializable")
TypeError: Object of type InvalidTextRepresentation is not JSON serializable
ERROR :- 2023-04-04 17:47:36,289 - app : Exception on /register [POST]
Traceback (most recent call last):
  File "/home/bc2113451/Desktop/VS Code/Oops/Library/app.py", line 40, in add_member
    cur.execute(add_query, values)
psycopg2.errors.InvalidTextRepresentation: invalid input syntax for type boolean: "1992-03-17"
LINE 2: ...d) VALUES ('Encyclopedia', 'Kabir', '1990-12-23', '1992-03-1...
                                                             ^


During handling of the above exception, another exception occurred:

Traceback (most recent call last):
  File "/home/bc2113451/Desktop/VS Code/Oops/.venv/lib/python3.8/site-packages/flask/app.py", line 2528, in wsgi_app
    response = self.full_dispatch_request()
  File "/home/bc2113451/Desktop/VS Code/Oops/.venv/lib/python3.8/site-packages/flask/app.py", line 1825, in full_dispatch_request
    rv = self.handle_user_exception(e)
  File "/home/bc2113451/Desktop/VS Code/Oops/.venv/lib/python3.8/site-packages/flask/app.py", line 1823, in full_dispatch_request
    rv = self.dispatch_request()
  File "/home/bc2113451/Desktop/VS Code/Oops/.venv/lib/python3.8/site-packages/flask/app.py", line 1799, in dispatch_request
    return self.ensure_sync(self.view_functions[rule.endpoint])(**view_args)
  File "/home/bc2113451/Desktop/VS Code/Oops/Library/app.py", line 48, in add_member
    return jsonify({"message": error})
  File "/home/bc2113451/Desktop/VS Code/Oops/.venv/lib/python3.8/site-packages/flask/json/__init__.py", line 342, in jsonify
    return current_app.json.response(*args, **kwargs)
  File "/home/bc2113451/Desktop/VS Code/Oops/.venv/lib/python3.8/site-packages/flask/json/provider.py", line 309, in response
    f"{self.dumps(obj, **dump_args)}\n", mimetype=mimetype
  File "/home/bc2113451/Desktop/VS Code/Oops/.venv/lib/python3.8/site-packages/flask/json/provider.py", line 230, in dumps
    return json.dumps(obj, **kwargs)
  File "/usr/lib/python3.8/json/__init__.py", line 234, in dumps
    return cls(
  File "/usr/lib/python3.8/json/encoder.py", line 199, in encode
    chunks = self.iterencode(o, _one_shot=True)
  File "/usr/lib/python3.8/json/encoder.py", line 257, in iterencode
    return _iterencode(o, 0)
  File "/home/bc2113451/Desktop/VS Code/Oops/.venv/lib/python3.8/site-packages/flask/json/provider.py", line 122, in _default
    raise TypeError(f"Object of type {type(o).__name__} is not JSON serializable")
TypeError: Object of type InvalidTextRepresentation is not JSON serializable
ERROR :- 2023-04-04 17:47:36,289 - app : Exception on /register [POST]
Traceback (most recent call last):
  File "/home/bc2113451/Desktop/VS Code/Oops/Library/app.py", line 40, in add_member
    cur.execute(add_query, values)
psycopg2.errors.InvalidTextRepresentation: invalid input syntax for type boolean: "1992-03-17"
LINE 2: ...d) VALUES ('Encyclopedia', 'Kabir', '1990-12-23', '1992-03-1...
                                                             ^


During handling of the above exception, another exception occurred:

Traceback (most recent call last):
  File "/home/bc2113451/Desktop/VS Code/Oops/.venv/lib/python3.8/site-packages/flask/app.py", line 2528, in wsgi_app
    response = self.full_dispatch_request()
  File "/home/bc2113451/Desktop/VS Code/Oops/.venv/lib/python3.8/site-packages/flask/app.py", line 1825, in full_dispatch_request
    rv = self.handle_user_exception(e)
  File "/home/bc2113451/Desktop/VS Code/Oops/.venv/lib/python3.8/site-packages/flask/app.py", line 1823, in full_dispatch_request
    rv = self.dispatch_request()
  File "/home/bc2113451/Desktop/VS Code/Oops/.venv/lib/python3.8/site-packages/flask/app.py", line 1799, in dispatch_request
    return self.ensure_sync(self.view_functions[rule.endpoint])(**view_args)
  File "/home/bc2113451/Desktop/VS Code/Oops/Library/app.py", line 48, in add_member
    return jsonify({"message": error})
  File "/home/bc2113451/Desktop/VS Code/Oops/.venv/lib/python3.8/site-packages/flask/json/__init__.py", line 342, in jsonify
    return current_app.json.response(*args, **kwargs)
  File "/home/bc2113451/Desktop/VS Code/Oops/.venv/lib/python3.8/site-packages/flask/json/provider.py", line 309, in response
    f"{self.dumps(obj, **dump_args)}\n", mimetype=mimetype
  File "/home/bc2113451/Desktop/VS Code/Oops/.venv/lib/python3.8/site-packages/flask/json/provider.py", line 230, in dumps
    return json.dumps(obj, **kwargs)
  File "/usr/lib/python3.8/json/__init__.py", line 234, in dumps
    return cls(
  File "/usr/lib/python3.8/json/encoder.py", line 199, in encode
    chunks = self.iterencode(o, _one_shot=True)
  File "/usr/lib/python3.8/json/encoder.py", line 257, in iterencode
    return _iterencode(o, 0)
  File "/home/bc2113451/Desktop/VS Code/Oops/.venv/lib/python3.8/site-packages/flask/json/provider.py", line 122, in _default
    raise TypeError(f"Object of type {type(o).__name__} is not JSON serializable")
TypeError: Object of type InvalidTextRepresentation is not JSON serializable
ERROR :- 2023-04-04 17:47:36,289 - app : Exception on /register [POST]
Traceback (most recent call last):
  File "/home/bc2113451/Desktop/VS Code/Oops/Library/app.py", line 40, in add_member
    cur.execute(add_query, values)
psycopg2.errors.InvalidTextRepresentation: invalid input syntax for type boolean: "1992-03-17"
LINE 2: ...d) VALUES ('Encyclopedia', 'Kabir', '1990-12-23', '1992-03-1...
                                                             ^


During handling of the above exception, another exception occurred:

Traceback (most recent call last):
  File "/home/bc2113451/Desktop/VS Code/Oops/.venv/lib/python3.8/site-packages/flask/app.py", line 2528, in wsgi_app
    response = self.full_dispatch_request()
  File "/home/bc2113451/Desktop/VS Code/Oops/.venv/lib/python3.8/site-packages/flask/app.py", line 1825, in full_dispatch_request
    rv = self.handle_user_exception(e)
  File "/home/bc2113451/Desktop/VS Code/Oops/.venv/lib/python3.8/site-packages/flask/app.py", line 1823, in full_dispatch_request
    rv = self.dispatch_request()
  File "/home/bc2113451/Desktop/VS Code/Oops/.venv/lib/python3.8/site-packages/flask/app.py", line 1799, in dispatch_request
    return self.ensure_sync(self.view_functions[rule.endpoint])(**view_args)
  File "/home/bc2113451/Desktop/VS Code/Oops/Library/app.py", line 48, in add_member
    return jsonify({"message": error})
  File "/home/bc2113451/Desktop/VS Code/Oops/.venv/lib/python3.8/site-packages/flask/json/__init__.py", line 342, in jsonify
    return current_app.json.response(*args, **kwargs)
  File "/home/bc2113451/Desktop/VS Code/Oops/.venv/lib/python3.8/site-packages/flask/json/provider.py", line 309, in response
    f"{self.dumps(obj, **dump_args)}\n", mimetype=mimetype
  File "/home/bc2113451/Desktop/VS Code/Oops/.venv/lib/python3.8/site-packages/flask/json/provider.py", line 230, in dumps
    return json.dumps(obj, **kwargs)
  File "/usr/lib/python3.8/json/__init__.py", line 234, in dumps
    return cls(
  File "/usr/lib/python3.8/json/encoder.py", line 199, in encode
    chunks = self.iterencode(o, _one_shot=True)
  File "/usr/lib/python3.8/json/encoder.py", line 257, in iterencode
    return _iterencode(o, 0)
  File "/home/bc2113451/Desktop/VS Code/Oops/.venv/lib/python3.8/site-packages/flask/json/provider.py", line 122, in _default
    raise TypeError(f"Object of type {type(o).__name__} is not JSON serializable")
TypeError: Object of type InvalidTextRepresentation is not JSON serializable
ERROR :- 2023-04-04 17:47:36,289 - app : Exception on /register [POST]
Traceback (most recent call last):
  File "/home/bc2113451/Desktop/VS Code/Oops/Library/app.py", line 40, in add_member
    cur.execute(add_query, values)
psycopg2.errors.InvalidTextRepresentation: invalid input syntax for type boolean: "1992-03-17"
LINE 2: ...d) VALUES ('Encyclopedia', 'Kabir', '1990-12-23', '1992-03-1...
                                                             ^


During handling of the above exception, another exception occurred:

Traceback (most recent call last):
  File "/home/bc2113451/Desktop/VS Code/Oops/.venv/lib/python3.8/site-packages/flask/app.py", line 2528, in wsgi_app
    response = self.full_dispatch_request()
  File "/home/bc2113451/Desktop/VS Code/Oops/.venv/lib/python3.8/site-packages/flask/app.py", line 1825, in full_dispatch_request
    rv = self.handle_user_exception(e)
  File "/home/bc2113451/Desktop/VS Code/Oops/.venv/lib/python3.8/site-packages/flask/app.py", line 1823, in full_dispatch_request
    rv = self.dispatch_request()
  File "/home/bc2113451/Desktop/VS Code/Oops/.venv/lib/python3.8/site-packages/flask/app.py", line 1799, in dispatch_request
    return self.ensure_sync(self.view_functions[rule.endpoint])(**view_args)
  File "/home/bc2113451/Desktop/VS Code/Oops/Library/app.py", line 48, in add_member
    return jsonify({"message": error})
  File "/home/bc2113451/Desktop/VS Code/Oops/.venv/lib/python3.8/site-packages/flask/json/__init__.py", line 342, in jsonify
    return current_app.json.response(*args, **kwargs)
  File "/home/bc2113451/Desktop/VS Code/Oops/.venv/lib/python3.8/site-packages/flask/json/provider.py", line 309, in response
    f"{self.dumps(obj, **dump_args)}\n", mimetype=mimetype
  File "/home/bc2113451/Desktop/VS Code/Oops/.venv/lib/python3.8/site-packages/flask/json/provider.py", line 230, in dumps
    return json.dumps(obj, **kwargs)
  File "/usr/lib/python3.8/json/__init__.py", line 234, in dumps
    return cls(
  File "/usr/lib/python3.8/json/encoder.py", line 199, in encode
    chunks = self.iterencode(o, _one_shot=True)
  File "/usr/lib/python3.8/json/encoder.py", line 257, in iterencode
    return _iterencode(o, 0)
  File "/home/bc2113451/Desktop/VS Code/Oops/.venv/lib/python3.8/site-packages/flask/json/provider.py", line 122, in _default
    raise TypeError(f"Object of type {type(o).__name__} is not JSON serializable")
TypeError: Object of type InvalidTextRepresentation is not JSON serializable
WARNING :- 2023-04-04 17:48:08,165 - app : Starting the db connection to display items in the cart
WARNING :- 2023-04-04 17:48:08,165 - app : Starting the db connection to display items in the cart
WARNING :- 2023-04-04 17:48:08,165 - app : Starting the db connection to display items in the cart
WARNING :- 2023-04-04 17:48:08,165 - app : Starting the db connection to display items in the cart
WARNING :- 2023-04-04 17:48:08,165 - app : Starting the db connection to display items in the cart
WARNING :- 2023-04-04 17:48:08,165 - app : Starting the db connection to display items in the cart
WARNING :- 2023-04-04 17:48:08,165 - app : Starting the db connection to display items in the cart
WARNING :- 2023-04-04 17:48:08,165 - app : Starting the db connection to display items in the cart
WARNING :- 2023-04-04 17:48:08,165 - app : Starting the db connection to display items in the cart
WARNING :- 2023-04-04 17:48:08,165 - app : Starting the db connection to display items in the cart
INFO :- 2023-04-04 17:48:08,374 - app : Kabir added in the list
INFO :- 2023-04-04 17:48:08,374 - app : Kabir added in the list
INFO :- 2023-04-04 17:48:08,374 - app : Kabir added in the list
INFO :- 2023-04-04 17:48:08,374 - app : Kabir added in the list
INFO :- 2023-04-04 17:48:08,374 - app : Kabir added in the list
INFO :- 2023-04-04 17:48:08,374 - app : Kabir added in the list
INFO :- 2023-04-04 17:48:08,374 - app : Kabir added in the list
INFO :- 2023-04-04 17:48:08,374 - app : Kabir added in the list
INFO :- 2023-04-04 17:48:08,374 - app : Kabir added in the list
INFO :- 2023-04-04 17:48:08,374 - app : Kabir added in the list
INFO :- 2023-04-04 17:48:08,374 - app : Kabir added in the list
WARNING :- 2023-04-04 17:48:08,375 - app : Hence member added, closing the connection
WARNING :- 2023-04-04 17:48:08,375 - app : Hence member added, closing the connection
WARNING :- 2023-04-04 17:48:08,375 - app : Hence member added, closing the connection
WARNING :- 2023-04-04 17:48:08,375 - app : Hence member added, closing the connection
WARNING :- 2023-04-04 17:48:08,375 - app : Hence member added, closing the connection
WARNING :- 2023-04-04 17:48:08,375 - app : Hence member added, closing the connection
WARNING :- 2023-04-04 17:48:08,375 - app : Hence member added, closing the connection
WARNING :- 2023-04-04 17:48:08,375 - app : Hence member added, closing the connection
WARNING :- 2023-04-04 17:48:08,375 - app : Hence member added, closing the connection
WARNING :- 2023-04-04 17:48:08,375 - app : Hence member added, closing the connection
WARNING :- 2023-04-04 17:48:08,375 - app : Hence member added, closing the connection
WARNING :- 2023-04-04 17:48:08,375 - app : Hence member added, closing the connection
WARNING :- 2023-04-04 17:48:21,985 - app : Starting the db connection to display members in the list
WARNING :- 2023-04-04 17:48:21,985 - app : Starting the db connection to display members in the list
WARNING :- 2023-04-04 17:48:21,985 - app : Starting the db connection to display members in the list
WARNING :- 2023-04-04 17:48:21,985 - app : Starting the db connection to display members in the list
WARNING :- 2023-04-04 17:48:21,985 - app : Starting the db connection to display members in the list
WARNING :- 2023-04-04 17:48:21,985 - app : Starting the db connection to display members in the list
WARNING :- 2023-04-04 17:48:21,985 - app : Starting the db connection to display members in the list
WARNING :- 2023-04-04 17:48:21,985 - app : Starting the db connection to display members in the list
WARNING :- 2023-04-04 17:48:21,985 - app : Starting the db connection to display members in the list
WARNING :- 2023-04-04 17:48:21,985 - app : Starting the db connection to display members in the list
WARNING :- 2023-04-04 17:48:21,985 - app : Starting the db connection to display members in the list
WARNING :- 2023-04-04 17:48:21,985 - app : Starting the db connection to display members in the list
WARNING :- 2023-04-04 17:48:21,985 - app : Starting the db connection to display members in the list
INFO :- 2023-04-04 17:48:22,310 - app : Displayed list of all member in the list
INFO :- 2023-04-04 17:48:22,310 - app : Displayed list of all member in the list
INFO :- 2023-04-04 17:48:22,310 - app : Displayed list of all member in the list
INFO :- 2023-04-04 17:48:22,310 - app : Displayed list of all member in the list
INFO :- 2023-04-04 17:48:22,310 - app : Displayed list of all member in the list
INFO :- 2023-04-04 17:48:22,310 - app : Displayed list of all member in the list
INFO :- 2023-04-04 17:48:22,310 - app : Displayed list of all member in the list
INFO :- 2023-04-04 17:48:22,310 - app : Displayed list of all member in the list
INFO :- 2023-04-04 17:48:22,310 - app : Displayed list of all member in the list
INFO :- 2023-04-04 17:48:22,310 - app : Displayed list of all member in the list
INFO :- 2023-04-04 17:48:22,310 - app : Displayed list of all member in the list
INFO :- 2023-04-04 17:48:22,310 - app : Displayed list of all member in the list
INFO :- 2023-04-04 17:48:22,310 - app : Displayed list of all member in the list
INFO :- 2023-04-04 17:48:22,310 - app : Displayed list of all member in the list
WARNING :- 2023-04-04 17:48:22,311 - app : Hence members displayed, closing the connection
WARNING :- 2023-04-04 17:48:22,311 - app : Hence members displayed, closing the connection
WARNING :- 2023-04-04 17:48:22,311 - app : Hence members displayed, closing the connection
WARNING :- 2023-04-04 17:48:22,311 - app : Hence members displayed, closing the connection
WARNING :- 2023-04-04 17:48:22,311 - app : Hence members displayed, closing the connection
WARNING :- 2023-04-04 17:48:22,311 - app : Hence members displayed, closing the connection
WARNING :- 2023-04-04 17:48:22,311 - app : Hence members displayed, closing the connection
WARNING :- 2023-04-04 17:48:22,311 - app : Hence members displayed, closing the connection
WARNING :- 2023-04-04 17:48:22,311 - app : Hence members displayed, closing the connection
WARNING :- 2023-04-04 17:48:22,311 - app : Hence members displayed, closing the connection
WARNING :- 2023-04-04 17:48:22,311 - app : Hence members displayed, closing the connection
WARNING :- 2023-04-04 17:48:22,311 - app : Hence members displayed, closing the connection
WARNING :- 2023-04-04 17:48:22,311 - app : Hence members displayed, closing the connection
WARNING :- 2023-04-04 17:48:22,311 - app : Hence members displayed, closing the connection
WARNING :- 2023-04-04 17:48:22,311 - app : Hence members displayed, closing the connection
WARNING :- 2023-04-04 17:54:02,782 - app : Starting the db connection to search user in the list
ERROR :- 2023-04-04 17:54:02,782 - app : Error occurred: not all arguments converted during string formatting
Traceback (most recent call last):
  File "/home/bc2113451/Desktop/VS Code/Oops/Library/app.py", line 134, in search_by_username
    cur.execute(show_query, username)
TypeError: not all arguments converted during string formatting
ERROR :- 2023-04-04 17:54:02,782 - app : Error occurred: not all arguments converted during string formatting
Traceback (most recent call last):
  File "/home/bc2113451/Desktop/VS Code/Oops/Library/app.py", line 134, in search_by_username
    cur.execute(show_query, username)
TypeError: not all arguments converted during string formatting
WARNING :- 2023-04-04 17:54:02,786 - app : Hence user searching done, closing the connection
WARNING :- 2023-04-04 17:54:02,786 - app : Hence user searching done, closing the connection
WARNING :- 2023-04-04 17:54:02,786 - app : Hence user searching done, closing the connection
ERROR :- 2023-04-04 17:54:02,786 - app : Exception on /search/Kabir [GET]
Traceback (most recent call last):
  File "/home/bc2113451/Desktop/VS Code/Oops/Library/app.py", line 134, in search_by_username
    cur.execute(show_query, username)
TypeError: not all arguments converted during string formatting

During handling of the above exception, another exception occurred:

Traceback (most recent call last):
  File "/home/bc2113451/Desktop/VS Code/Oops/.venv/lib/python3.8/site-packages/flask/app.py", line 2528, in wsgi_app
    response = self.full_dispatch_request()
  File "/home/bc2113451/Desktop/VS Code/Oops/.venv/lib/python3.8/site-packages/flask/app.py", line 1825, in full_dispatch_request
    rv = self.handle_user_exception(e)
  File "/home/bc2113451/Desktop/VS Code/Oops/.venv/lib/python3.8/site-packages/flask/app.py", line 1823, in full_dispatch_request
    rv = self.dispatch_request()
  File "/home/bc2113451/Desktop/VS Code/Oops/.venv/lib/python3.8/site-packages/flask/app.py", line 1799, in dispatch_request
    return self.ensure_sync(self.view_functions[rule.endpoint])(**view_args)
  File "/home/bc2113451/Desktop/VS Code/Oops/Library/app.py", line 144, in search_by_username
    return jsonify({"message": error})
  File "/home/bc2113451/Desktop/VS Code/Oops/.venv/lib/python3.8/site-packages/flask/json/__init__.py", line 342, in jsonify
    return current_app.json.response(*args, **kwargs)
  File "/home/bc2113451/Desktop/VS Code/Oops/.venv/lib/python3.8/site-packages/flask/json/provider.py", line 309, in response
    f"{self.dumps(obj, **dump_args)}\n", mimetype=mimetype
  File "/home/bc2113451/Desktop/VS Code/Oops/.venv/lib/python3.8/site-packages/flask/json/provider.py", line 230, in dumps
    return json.dumps(obj, **kwargs)
  File "/usr/lib/python3.8/json/__init__.py", line 234, in dumps
    return cls(
  File "/usr/lib/python3.8/json/encoder.py", line 199, in encode
    chunks = self.iterencode(o, _one_shot=True)
  File "/usr/lib/python3.8/json/encoder.py", line 257, in iterencode
    return _iterencode(o, 0)
  File "/home/bc2113451/Desktop/VS Code/Oops/.venv/lib/python3.8/site-packages/flask/json/provider.py", line 122, in _default
    raise TypeError(f"Object of type {type(o).__name__} is not JSON serializable")
TypeError: Object of type TypeError is not JSON serializable
ERROR :- 2023-04-04 17:54:02,786 - app : Exception on /search/Kabir [GET]
Traceback (most recent call last):
  File "/home/bc2113451/Desktop/VS Code/Oops/Library/app.py", line 134, in search_by_username
    cur.execute(show_query, username)
TypeError: not all arguments converted during string formatting

During handling of the above exception, another exception occurred:

Traceback (most recent call last):
  File "/home/bc2113451/Desktop/VS Code/Oops/.venv/lib/python3.8/site-packages/flask/app.py", line 2528, in wsgi_app
    response = self.full_dispatch_request()
  File "/home/bc2113451/Desktop/VS Code/Oops/.venv/lib/python3.8/site-packages/flask/app.py", line 1825, in full_dispatch_request
    rv = self.handle_user_exception(e)
  File "/home/bc2113451/Desktop/VS Code/Oops/.venv/lib/python3.8/site-packages/flask/app.py", line 1823, in full_dispatch_request
    rv = self.dispatch_request()
  File "/home/bc2113451/Desktop/VS Code/Oops/.venv/lib/python3.8/site-packages/flask/app.py", line 1799, in dispatch_request
    return self.ensure_sync(self.view_functions[rule.endpoint])(**view_args)
  File "/home/bc2113451/Desktop/VS Code/Oops/Library/app.py", line 144, in search_by_username
    return jsonify({"message": error})
  File "/home/bc2113451/Desktop/VS Code/Oops/.venv/lib/python3.8/site-packages/flask/json/__init__.py", line 342, in jsonify
    return current_app.json.response(*args, **kwargs)
  File "/home/bc2113451/Desktop/VS Code/Oops/.venv/lib/python3.8/site-packages/flask/json/provider.py", line 309, in response
    f"{self.dumps(obj, **dump_args)}\n", mimetype=mimetype
  File "/home/bc2113451/Desktop/VS Code/Oops/.venv/lib/python3.8/site-packages/flask/json/provider.py", line 230, in dumps
    return json.dumps(obj, **kwargs)
  File "/usr/lib/python3.8/json/__init__.py", line 234, in dumps
    return cls(
  File "/usr/lib/python3.8/json/encoder.py", line 199, in encode
    chunks = self.iterencode(o, _one_shot=True)
  File "/usr/lib/python3.8/json/encoder.py", line 257, in iterencode
    return _iterencode(o, 0)
  File "/home/bc2113451/Desktop/VS Code/Oops/.venv/lib/python3.8/site-packages/flask/json/provider.py", line 122, in _default
    raise TypeError(f"Object of type {type(o).__name__} is not JSON serializable")
TypeError: Object of type TypeError is not JSON serializable
ERROR :- 2023-04-04 17:54:02,786 - app : Exception on /search/Kabir [GET]
Traceback (most recent call last):
  File "/home/bc2113451/Desktop/VS Code/Oops/Library/app.py", line 134, in search_by_username
    cur.execute(show_query, username)
TypeError: not all arguments converted during string formatting

During handling of the above exception, another exception occurred:

Traceback (most recent call last):
  File "/home/bc2113451/Desktop/VS Code/Oops/.venv/lib/python3.8/site-packages/flask/app.py", line 2528, in wsgi_app
    response = self.full_dispatch_request()
  File "/home/bc2113451/Desktop/VS Code/Oops/.venv/lib/python3.8/site-packages/flask/app.py", line 1825, in full_dispatch_request
    rv = self.handle_user_exception(e)
  File "/home/bc2113451/Desktop/VS Code/Oops/.venv/lib/python3.8/site-packages/flask/app.py", line 1823, in full_dispatch_request
    rv = self.dispatch_request()
  File "/home/bc2113451/Desktop/VS Code/Oops/.venv/lib/python3.8/site-packages/flask/app.py", line 1799, in dispatch_request
    return self.ensure_sync(self.view_functions[rule.endpoint])(**view_args)
  File "/home/bc2113451/Desktop/VS Code/Oops/Library/app.py", line 144, in search_by_username
    return jsonify({"message": error})
  File "/home/bc2113451/Desktop/VS Code/Oops/.venv/lib/python3.8/site-packages/flask/json/__init__.py", line 342, in jsonify
    return current_app.json.response(*args, **kwargs)
  File "/home/bc2113451/Desktop/VS Code/Oops/.venv/lib/python3.8/site-packages/flask/json/provider.py", line 309, in response
    f"{self.dumps(obj, **dump_args)}\n", mimetype=mimetype
  File "/home/bc2113451/Desktop/VS Code/Oops/.venv/lib/python3.8/site-packages/flask/json/provider.py", line 230, in dumps
    return json.dumps(obj, **kwargs)
  File "/usr/lib/python3.8/json/__init__.py", line 234, in dumps
    return cls(
  File "/usr/lib/python3.8/json/encoder.py", line 199, in encode
    chunks = self.iterencode(o, _one_shot=True)
  File "/usr/lib/python3.8/json/encoder.py", line 257, in iterencode
    return _iterencode(o, 0)
  File "/home/bc2113451/Desktop/VS Code/Oops/.venv/lib/python3.8/site-packages/flask/json/provider.py", line 122, in _default
    raise TypeError(f"Object of type {type(o).__name__} is not JSON serializable")
TypeError: Object of type TypeError is not JSON serializable
WARNING :- 2023-04-04 17:54:31,702 - app : Starting the db connection to search user in the list
ERROR :- 2023-04-04 17:54:32,120 - app : Error occurred: column "username" does not exist
LINE 1: SELECT * FROM cart WHERE username = 'Kabir';
                                 ^
Traceback (most recent call last):
  File "/home/bc2113451/Desktop/VS Code/Oops/Library/app.py", line 134, in search_by_username
    cur.execute(show_query, (username, ))
psycopg2.errors.UndefinedColumn: column "username" does not exist
LINE 1: SELECT * FROM cart WHERE username = 'Kabir';
                                 ^

ERROR :- 2023-04-04 17:54:32,120 - app : Error occurred: column "username" does not exist
LINE 1: SELECT * FROM cart WHERE username = 'Kabir';
                                 ^
Traceback (most recent call last):
  File "/home/bc2113451/Desktop/VS Code/Oops/Library/app.py", line 134, in search_by_username
    cur.execute(show_query, (username, ))
psycopg2.errors.UndefinedColumn: column "username" does not exist
LINE 1: SELECT * FROM cart WHERE username = 'Kabir';
                                 ^

WARNING :- 2023-04-04 17:54:32,122 - app : Hence user searching done, closing the connection
WARNING :- 2023-04-04 17:54:32,122 - app : Hence user searching done, closing the connection
WARNING :- 2023-04-04 17:54:32,122 - app : Hence user searching done, closing the connection
ERROR :- 2023-04-04 17:54:32,123 - app : Exception on /search/Kabir [GET]
Traceback (most recent call last):
  File "/home/bc2113451/Desktop/VS Code/Oops/Library/app.py", line 134, in search_by_username
    cur.execute(show_query, (username, ))
psycopg2.errors.UndefinedColumn: column "username" does not exist
LINE 1: SELECT * FROM cart WHERE username = 'Kabir';
                                 ^


During handling of the above exception, another exception occurred:

Traceback (most recent call last):
  File "/home/bc2113451/Desktop/VS Code/Oops/.venv/lib/python3.8/site-packages/flask/app.py", line 2528, in wsgi_app
    response = self.full_dispatch_request()
  File "/home/bc2113451/Desktop/VS Code/Oops/.venv/lib/python3.8/site-packages/flask/app.py", line 1825, in full_dispatch_request
    rv = self.handle_user_exception(e)
  File "/home/bc2113451/Desktop/VS Code/Oops/.venv/lib/python3.8/site-packages/flask/app.py", line 1823, in full_dispatch_request
    rv = self.dispatch_request()
  File "/home/bc2113451/Desktop/VS Code/Oops/.venv/lib/python3.8/site-packages/flask/app.py", line 1799, in dispatch_request
    return self.ensure_sync(self.view_functions[rule.endpoint])(**view_args)
  File "/home/bc2113451/Desktop/VS Code/Oops/Library/app.py", line 144, in search_by_username
    return jsonify({"message": error})
  File "/home/bc2113451/Desktop/VS Code/Oops/.venv/lib/python3.8/site-packages/flask/json/__init__.py", line 342, in jsonify
    return current_app.json.response(*args, **kwargs)
  File "/home/bc2113451/Desktop/VS Code/Oops/.venv/lib/python3.8/site-packages/flask/json/provider.py", line 309, in response
    f"{self.dumps(obj, **dump_args)}\n", mimetype=mimetype
  File "/home/bc2113451/Desktop/VS Code/Oops/.venv/lib/python3.8/site-packages/flask/json/provider.py", line 230, in dumps
    return json.dumps(obj, **kwargs)
  File "/usr/lib/python3.8/json/__init__.py", line 234, in dumps
    return cls(
  File "/usr/lib/python3.8/json/encoder.py", line 199, in encode
    chunks = self.iterencode(o, _one_shot=True)
  File "/usr/lib/python3.8/json/encoder.py", line 257, in iterencode
    return _iterencode(o, 0)
  File "/home/bc2113451/Desktop/VS Code/Oops/.venv/lib/python3.8/site-packages/flask/json/provider.py", line 122, in _default
    raise TypeError(f"Object of type {type(o).__name__} is not JSON serializable")
TypeError: Object of type UndefinedColumn is not JSON serializable
ERROR :- 2023-04-04 17:54:32,123 - app : Exception on /search/Kabir [GET]
Traceback (most recent call last):
  File "/home/bc2113451/Desktop/VS Code/Oops/Library/app.py", line 134, in search_by_username
    cur.execute(show_query, (username, ))
psycopg2.errors.UndefinedColumn: column "username" does not exist
LINE 1: SELECT * FROM cart WHERE username = 'Kabir';
                                 ^


During handling of the above exception, another exception occurred:

Traceback (most recent call last):
  File "/home/bc2113451/Desktop/VS Code/Oops/.venv/lib/python3.8/site-packages/flask/app.py", line 2528, in wsgi_app
    response = self.full_dispatch_request()
  File "/home/bc2113451/Desktop/VS Code/Oops/.venv/lib/python3.8/site-packages/flask/app.py", line 1825, in full_dispatch_request
    rv = self.handle_user_exception(e)
  File "/home/bc2113451/Desktop/VS Code/Oops/.venv/lib/python3.8/site-packages/flask/app.py", line 1823, in full_dispatch_request
    rv = self.dispatch_request()
  File "/home/bc2113451/Desktop/VS Code/Oops/.venv/lib/python3.8/site-packages/flask/app.py", line 1799, in dispatch_request
    return self.ensure_sync(self.view_functions[rule.endpoint])(**view_args)
  File "/home/bc2113451/Desktop/VS Code/Oops/Library/app.py", line 144, in search_by_username
    return jsonify({"message": error})
  File "/home/bc2113451/Desktop/VS Code/Oops/.venv/lib/python3.8/site-packages/flask/json/__init__.py", line 342, in jsonify
    return current_app.json.response(*args, **kwargs)
  File "/home/bc2113451/Desktop/VS Code/Oops/.venv/lib/python3.8/site-packages/flask/json/provider.py", line 309, in response
    f"{self.dumps(obj, **dump_args)}\n", mimetype=mimetype
  File "/home/bc2113451/Desktop/VS Code/Oops/.venv/lib/python3.8/site-packages/flask/json/provider.py", line 230, in dumps
    return json.dumps(obj, **kwargs)
  File "/usr/lib/python3.8/json/__init__.py", line 234, in dumps
    return cls(
  File "/usr/lib/python3.8/json/encoder.py", line 199, in encode
    chunks = self.iterencode(o, _one_shot=True)
  File "/usr/lib/python3.8/json/encoder.py", line 257, in iterencode
    return _iterencode(o, 0)
  File "/home/bc2113451/Desktop/VS Code/Oops/.venv/lib/python3.8/site-packages/flask/json/provider.py", line 122, in _default
    raise TypeError(f"Object of type {type(o).__name__} is not JSON serializable")
TypeError: Object of type UndefinedColumn is not JSON serializable
ERROR :- 2023-04-04 17:54:32,123 - app : Exception on /search/Kabir [GET]
Traceback (most recent call last):
  File "/home/bc2113451/Desktop/VS Code/Oops/Library/app.py", line 134, in search_by_username
    cur.execute(show_query, (username, ))
psycopg2.errors.UndefinedColumn: column "username" does not exist
LINE 1: SELECT * FROM cart WHERE username = 'Kabir';
                                 ^


During handling of the above exception, another exception occurred:

Traceback (most recent call last):
  File "/home/bc2113451/Desktop/VS Code/Oops/.venv/lib/python3.8/site-packages/flask/app.py", line 2528, in wsgi_app
    response = self.full_dispatch_request()
  File "/home/bc2113451/Desktop/VS Code/Oops/.venv/lib/python3.8/site-packages/flask/app.py", line 1825, in full_dispatch_request
    rv = self.handle_user_exception(e)
  File "/home/bc2113451/Desktop/VS Code/Oops/.venv/lib/python3.8/site-packages/flask/app.py", line 1823, in full_dispatch_request
    rv = self.dispatch_request()
  File "/home/bc2113451/Desktop/VS Code/Oops/.venv/lib/python3.8/site-packages/flask/app.py", line 1799, in dispatch_request
    return self.ensure_sync(self.view_functions[rule.endpoint])(**view_args)
  File "/home/bc2113451/Desktop/VS Code/Oops/Library/app.py", line 144, in search_by_username
    return jsonify({"message": error})
  File "/home/bc2113451/Desktop/VS Code/Oops/.venv/lib/python3.8/site-packages/flask/json/__init__.py", line 342, in jsonify
    return current_app.json.response(*args, **kwargs)
  File "/home/bc2113451/Desktop/VS Code/Oops/.venv/lib/python3.8/site-packages/flask/json/provider.py", line 309, in response
    f"{self.dumps(obj, **dump_args)}\n", mimetype=mimetype
  File "/home/bc2113451/Desktop/VS Code/Oops/.venv/lib/python3.8/site-packages/flask/json/provider.py", line 230, in dumps
    return json.dumps(obj, **kwargs)
  File "/usr/lib/python3.8/json/__init__.py", line 234, in dumps
    return cls(
  File "/usr/lib/python3.8/json/encoder.py", line 199, in encode
    chunks = self.iterencode(o, _one_shot=True)
  File "/usr/lib/python3.8/json/encoder.py", line 257, in iterencode
    return _iterencode(o, 0)
  File "/home/bc2113451/Desktop/VS Code/Oops/.venv/lib/python3.8/site-packages/flask/json/provider.py", line 122, in _default
    raise TypeError(f"Object of type {type(o).__name__} is not JSON serializable")
TypeError: Object of type UndefinedColumn is not JSON serializable
WARNING :- 2023-04-04 17:54:57,167 - app : Starting the db connection to search user in the list
INFO :- 2023-04-04 17:54:57,521 - app : Displayed details of the member in the list
INFO :- 2023-04-04 17:54:57,521 - app : Displayed details of the member in the list
WARNING :- 2023-04-04 17:54:57,522 - app : Hence user searching done, closing the connection
WARNING :- 2023-04-04 17:54:57,522 - app : Hence user searching done, closing the connection
WARNING :- 2023-04-04 17:54:57,522 - app : Hence user searching done, closing the connection
WARNING :- 2023-04-04 17:58:25,879 - app : Starting the db connection to display borrow history in the list
INFO :- 2023-04-04 17:58:26,648 - app : Displayed details of the book type in the list
INFO :- 2023-04-04 17:58:26,648 - app : Displayed details of the book type in the list
WARNING :- 2023-04-04 17:58:26,651 - app : Hence borrowed history displayed, closing the connection
WARNING :- 2023-04-04 17:58:26,651 - app : Hence borrowed history displayed, closing the connection
WARNING :- 2023-04-04 17:58:26,651 - app : Hence borrowed history displayed, closing the connection
WARNING :- 2023-04-04 18:06:59,731 - app : Starting the db connection to generate report of books in the list
ERROR :- 2023-04-04 18:06:59,940 - app : Error occurred: column "library.type" must appear in the GROUP BY clause or be used in an aggregate function
LINE 1: SELECT type, COUNT(*) AS borrow_Count FROM library WHERE typ...
               ^
Traceback (most recent call last):
  File "/home/bc2113451/Desktop/VS Code/Oops/Library/app.py", line 184, in generate_report
    cur.execute(show_query, (type, ))
psycopg2.errors.GroupingError: column "library.type" must appear in the GROUP BY clause or be used in an aggregate function
LINE 1: SELECT type, COUNT(*) AS borrow_Count FROM library WHERE typ...
               ^

ERROR :- 2023-04-04 18:06:59,940 - app : Error occurred: column "library.type" must appear in the GROUP BY clause or be used in an aggregate function
LINE 1: SELECT type, COUNT(*) AS borrow_Count FROM library WHERE typ...
               ^
Traceback (most recent call last):
  File "/home/bc2113451/Desktop/VS Code/Oops/Library/app.py", line 184, in generate_report
    cur.execute(show_query, (type, ))
psycopg2.errors.GroupingError: column "library.type" must appear in the GROUP BY clause or be used in an aggregate function
LINE 1: SELECT type, COUNT(*) AS borrow_Count FROM library WHERE typ...
               ^

WARNING :- 2023-04-04 18:06:59,941 - app : Hence report has been generated, closing the connection
WARNING :- 2023-04-04 18:06:59,941 - app : Hence report has been generated, closing the connection
WARNING :- 2023-04-04 18:06:59,941 - app : Hence report has been generated, closing the connection
ERROR :- 2023-04-04 18:06:59,941 - app : Exception on /report/Journal [GET]
Traceback (most recent call last):
  File "/home/bc2113451/Desktop/VS Code/Oops/Library/app.py", line 184, in generate_report
    cur.execute(show_query, (type, ))
psycopg2.errors.GroupingError: column "library.type" must appear in the GROUP BY clause or be used in an aggregate function
LINE 1: SELECT type, COUNT(*) AS borrow_Count FROM library WHERE typ...
               ^


During handling of the above exception, another exception occurred:

Traceback (most recent call last):
  File "/home/bc2113451/Desktop/VS Code/Oops/.venv/lib/python3.8/site-packages/flask/app.py", line 2528, in wsgi_app
    response = self.full_dispatch_request()
  File "/home/bc2113451/Desktop/VS Code/Oops/.venv/lib/python3.8/site-packages/flask/app.py", line 1825, in full_dispatch_request
    rv = self.handle_user_exception(e)
  File "/home/bc2113451/Desktop/VS Code/Oops/.venv/lib/python3.8/site-packages/flask/app.py", line 1823, in full_dispatch_request
    rv = self.dispatch_request()
  File "/home/bc2113451/Desktop/VS Code/Oops/.venv/lib/python3.8/site-packages/flask/app.py", line 1799, in dispatch_request
    return self.ensure_sync(self.view_functions[rule.endpoint])(**view_args)
  File "/home/bc2113451/Desktop/VS Code/Oops/Library/app.py", line 194, in generate_report
    return jsonify({"message": error})
  File "/home/bc2113451/Desktop/VS Code/Oops/.venv/lib/python3.8/site-packages/flask/json/__init__.py", line 342, in jsonify
    return current_app.json.response(*args, **kwargs)
  File "/home/bc2113451/Desktop/VS Code/Oops/.venv/lib/python3.8/site-packages/flask/json/provider.py", line 309, in response
    f"{self.dumps(obj, **dump_args)}\n", mimetype=mimetype
  File "/home/bc2113451/Desktop/VS Code/Oops/.venv/lib/python3.8/site-packages/flask/json/provider.py", line 230, in dumps
    return json.dumps(obj, **kwargs)
  File "/usr/lib/python3.8/json/__init__.py", line 234, in dumps
    return cls(
  File "/usr/lib/python3.8/json/encoder.py", line 199, in encode
    chunks = self.iterencode(o, _one_shot=True)
  File "/usr/lib/python3.8/json/encoder.py", line 257, in iterencode
    return _iterencode(o, 0)
  File "/home/bc2113451/Desktop/VS Code/Oops/.venv/lib/python3.8/site-packages/flask/json/provider.py", line 122, in _default
    raise TypeError(f"Object of type {type(o).__name__} is not JSON serializable")
TypeError: Object of type GroupingError is not JSON serializable
ERROR :- 2023-04-04 18:06:59,941 - app : Exception on /report/Journal [GET]
Traceback (most recent call last):
  File "/home/bc2113451/Desktop/VS Code/Oops/Library/app.py", line 184, in generate_report
    cur.execute(show_query, (type, ))
psycopg2.errors.GroupingError: column "library.type" must appear in the GROUP BY clause or be used in an aggregate function
LINE 1: SELECT type, COUNT(*) AS borrow_Count FROM library WHERE typ...
               ^


During handling of the above exception, another exception occurred:

Traceback (most recent call last):
  File "/home/bc2113451/Desktop/VS Code/Oops/.venv/lib/python3.8/site-packages/flask/app.py", line 2528, in wsgi_app
    response = self.full_dispatch_request()
  File "/home/bc2113451/Desktop/VS Code/Oops/.venv/lib/python3.8/site-packages/flask/app.py", line 1825, in full_dispatch_request
    rv = self.handle_user_exception(e)
  File "/home/bc2113451/Desktop/VS Code/Oops/.venv/lib/python3.8/site-packages/flask/app.py", line 1823, in full_dispatch_request
    rv = self.dispatch_request()
  File "/home/bc2113451/Desktop/VS Code/Oops/.venv/lib/python3.8/site-packages/flask/app.py", line 1799, in dispatch_request
    return self.ensure_sync(self.view_functions[rule.endpoint])(**view_args)
  File "/home/bc2113451/Desktop/VS Code/Oops/Library/app.py", line 194, in generate_report
    return jsonify({"message": error})
  File "/home/bc2113451/Desktop/VS Code/Oops/.venv/lib/python3.8/site-packages/flask/json/__init__.py", line 342, in jsonify
    return current_app.json.response(*args, **kwargs)
  File "/home/bc2113451/Desktop/VS Code/Oops/.venv/lib/python3.8/site-packages/flask/json/provider.py", line 309, in response
    f"{self.dumps(obj, **dump_args)}\n", mimetype=mimetype
  File "/home/bc2113451/Desktop/VS Code/Oops/.venv/lib/python3.8/site-packages/flask/json/provider.py", line 230, in dumps
    return json.dumps(obj, **kwargs)
  File "/usr/lib/python3.8/json/__init__.py", line 234, in dumps
    return cls(
  File "/usr/lib/python3.8/json/encoder.py", line 199, in encode
    chunks = self.iterencode(o, _one_shot=True)
  File "/usr/lib/python3.8/json/encoder.py", line 257, in iterencode
    return _iterencode(o, 0)
  File "/home/bc2113451/Desktop/VS Code/Oops/.venv/lib/python3.8/site-packages/flask/json/provider.py", line 122, in _default
    raise TypeError(f"Object of type {type(o).__name__} is not JSON serializable")
TypeError: Object of type GroupingError is not JSON serializable
ERROR :- 2023-04-04 18:06:59,941 - app : Exception on /report/Journal [GET]
Traceback (most recent call last):
  File "/home/bc2113451/Desktop/VS Code/Oops/Library/app.py", line 184, in generate_report
    cur.execute(show_query, (type, ))
psycopg2.errors.GroupingError: column "library.type" must appear in the GROUP BY clause or be used in an aggregate function
LINE 1: SELECT type, COUNT(*) AS borrow_Count FROM library WHERE typ...
               ^


During handling of the above exception, another exception occurred:

Traceback (most recent call last):
  File "/home/bc2113451/Desktop/VS Code/Oops/.venv/lib/python3.8/site-packages/flask/app.py", line 2528, in wsgi_app
    response = self.full_dispatch_request()
  File "/home/bc2113451/Desktop/VS Code/Oops/.venv/lib/python3.8/site-packages/flask/app.py", line 1825, in full_dispatch_request
    rv = self.handle_user_exception(e)
  File "/home/bc2113451/Desktop/VS Code/Oops/.venv/lib/python3.8/site-packages/flask/app.py", line 1823, in full_dispatch_request
    rv = self.dispatch_request()
  File "/home/bc2113451/Desktop/VS Code/Oops/.venv/lib/python3.8/site-packages/flask/app.py", line 1799, in dispatch_request
    return self.ensure_sync(self.view_functions[rule.endpoint])(**view_args)
  File "/home/bc2113451/Desktop/VS Code/Oops/Library/app.py", line 194, in generate_report
    return jsonify({"message": error})
  File "/home/bc2113451/Desktop/VS Code/Oops/.venv/lib/python3.8/site-packages/flask/json/__init__.py", line 342, in jsonify
    return current_app.json.response(*args, **kwargs)
  File "/home/bc2113451/Desktop/VS Code/Oops/.venv/lib/python3.8/site-packages/flask/json/provider.py", line 309, in response
    f"{self.dumps(obj, **dump_args)}\n", mimetype=mimetype
  File "/home/bc2113451/Desktop/VS Code/Oops/.venv/lib/python3.8/site-packages/flask/json/provider.py", line 230, in dumps
    return json.dumps(obj, **kwargs)
  File "/usr/lib/python3.8/json/__init__.py", line 234, in dumps
    return cls(
  File "/usr/lib/python3.8/json/encoder.py", line 199, in encode
    chunks = self.iterencode(o, _one_shot=True)
  File "/usr/lib/python3.8/json/encoder.py", line 257, in iterencode
    return _iterencode(o, 0)
  File "/home/bc2113451/Desktop/VS Code/Oops/.venv/lib/python3.8/site-packages/flask/json/provider.py", line 122, in _default
    raise TypeError(f"Object of type {type(o).__name__} is not JSON serializable")
TypeError: Object of type GroupingError is not JSON serializable
WARNING :- 2023-04-04 18:07:43,239 - app : Starting the db connection to generate report of books in the list
INFO :- 2023-04-04 18:07:43,379 - app : Generate report of book type in the list
INFO :- 2023-04-04 18:07:43,379 - app : Generate report of book type in the list
WARNING :- 2023-04-04 18:07:43,379 - app : Hence report has been generated, closing the connection
WARNING :- 2023-04-04 18:07:43,379 - app : Hence report has been generated, closing the connection
WARNING :- 2023-04-04 18:07:43,379 - app : Hence report has been generated, closing the connection
WARNING :- 2023-04-05 12:40:59,580 - app : Starting the db connection to display members in the list
INFO :- 2023-04-05 12:40:59,964 - app : Displayed list of all member in the list
INFO :- 2023-04-05 12:40:59,964 - app : Displayed list of all member in the list
WARNING :- 2023-04-05 12:40:59,965 - app : Closing the connection
WARNING :- 2023-04-05 12:40:59,965 - app : Closing the connection
WARNING :- 2023-04-05 12:40:59,965 - app : Closing the connection
WARNING :- 2023-04-13 10:39:40,067 - app : Starting the db connection to display borrow history in the list
INFO :- 2023-04-13 10:39:40,212 - app : Displayed details of the book Journal in the list
INFO :- 2023-04-13 10:39:40,212 - app : Displayed details of the book Journal in the list
WARNING :- 2023-04-13 10:39:40,213 - settings : Hence account created, closing the connection
WARNING :- 2023-04-13 10:41:00,252 - app : Starting the db connection to display borrow history in the list
INFO :- 2023-04-13 10:41:00,395 - app : Journal has been taken (1,) as shown in the list
INFO :- 2023-04-13 10:41:00,395 - app : Journal has been taken (1,) as shown in the list
WARNING :- 2023-04-13 10:41:00,396 - settings : Hence account created, closing the connection
WARNING :- 2023-04-13 10:41:18,255 - app : Starting the db connection to display borrow history in the list
INFO :- 2023-04-13 10:41:18,384 - app : Journal has been taken 1 as shown in the list
INFO :- 2023-04-13 10:41:18,384 - app : Journal has been taken 1 as shown in the list
WARNING :- 2023-04-13 10:41:18,385 - settings : Hence account created, closing the connection
WARNING :- 2023-04-13 10:42:29,432 - app : Starting the db connection to display borrow history in the list
INFO :- 2023-04-13 10:42:29,569 - app : Journal has been taken 1 number of times as shown in the list
INFO :- 2023-04-13 10:42:29,569 - app : Journal has been taken 1 number of times as shown in the list
WARNING :- 2023-04-13 10:42:29,570 - settings : Hence account created, closing the connection
WARNING :- 2023-04-13 10:42:45,594 - app : Starting the db connection to generate report of books in the list
WARNING :- 2023-04-13 10:42:45,594 - app : Starting the db connection to generate report of books in the list
WARNING :- 2023-04-13 10:42:45,594 - app : Starting the db connection to generate report of books in the list
INFO :- 2023-04-13 10:42:45,722 - app : Report of Journal generated in the list
INFO :- 2023-04-13 10:42:45,722 - app : Report of Journal generated in the list
INFO :- 2023-04-13 10:42:45,722 - app : Report of Journal generated in the list
INFO :- 2023-04-13 10:42:45,722 - app : Report of Journal generated in the list
WARNING :- 2023-04-13 10:42:45,723 - settings : Hence account created, closing the connection
WARNING :- 2023-04-13 10:42:45,723 - settings : Hence account created, closing the connection
WARNING :- 2023-04-13 10:45:42,705 - app : Starting the db connection to update the details 
WARNING :- 2023-04-13 10:45:42,705 - app : Starting the db connection to update the details 
WARNING :- 2023-04-13 10:45:42,705 - app : Starting the db connection to update the details 
WARNING :- 2023-04-13 10:45:42,705 - app : Starting the db connection to update the details 
WARNING :- 2023-04-13 10:45:42,705 - app : Starting the db connection to update the details 
INFO :- 2023-04-13 10:45:42,885 - app : Member details updated: {'bookName': 'Mein campf'}
INFO :- 2023-04-13 10:45:42,885 - app : Member details updated: {'bookName': 'Mein campf'}
INFO :- 2023-04-13 10:45:42,885 - app : Member details updated: {'bookName': 'Mein campf'}
INFO :- 2023-04-13 10:45:42,885 - app : Member details updated: {'bookName': 'Mein campf'}
INFO :- 2023-04-13 10:45:42,885 - app : Member details updated: {'bookName': 'Mein campf'}
INFO :- 2023-04-13 10:45:42,885 - app : Member details updated: {'bookName': 'Mein campf'}
WARNING :- 2023-04-13 10:45:42,885 - settings : Hence account created, closing the connection
WARNING :- 2023-04-13 10:45:42,885 - settings : Hence account created, closing the connection
WARNING :- 2023-04-13 10:45:42,885 - settings : Hence account created, closing the connection
WARNING :- 2023-04-13 10:47:43,367 - app : Starting the db connection to update the details 
INFO :- 2023-04-13 10:47:43,550 - app : Member details updated: {'bookName': 'Mein campf'}
INFO :- 2023-04-13 10:47:43,550 - app : Member details updated: {'bookName': 'Mein campf'}
WARNING :- 2023-04-13 10:47:43,551 - settings : Hence account created, closing the connection
WARNING :- 2023-04-13 10:48:42,020 - app : Starting the db connection to update the details 
INFO :- 2023-04-13 10:48:42,202 - app : Details of None has been updated to {'bookName': 'Mein campf'}
INFO :- 2023-04-13 10:48:42,202 - app : Details of None has been updated to {'bookName': 'Mein campf'}
WARNING :- 2023-04-13 10:48:42,203 - settings : Hence account created, closing the connection
WARNING :- 2023-04-13 10:49:26,325 - app : Starting the db connection to update the details 
INFO :- 2023-04-13 10:49:26,505 - app : Details of Anjali has been updated to {'bookName': 'Mein campf'}
INFO :- 2023-04-13 10:49:26,505 - app : Details of Anjali has been updated to {'bookName': 'Mein campf'}
WARNING :- 2023-04-13 10:49:26,506 - settings : Hence account created, closing the connection
WARNING :- 2023-04-13 11:03:43,302 - app : Starting the db connection to generate report of books in the list
WARNING :- 2023-04-13 11:03:43,665 - settings : Hence account created, closing the connection
ERROR :- 2023-04-13 11:03:43,665 - app : Exception on /reviews/1 [PUT]
Traceback (most recent call last):
  File "/home/bc2113451/Desktop/VS Code/Oops/Library/settings.py", line 31, in wrapper
    return func(*args, **kwargs)
  File "/home/bc2113451/Desktop/VS Code/Oops/Library/app.py", line 217, in add_reviews
    get_username = get_member[0]
TypeError: 'NoneType' object is not subscriptable

During handling of the above exception, another exception occurred:

Traceback (most recent call last):
  File "/home/bc2113451/Desktop/VS Code/Oops/.venv/lib/python3.8/site-packages/flask/app.py", line 2528, in wsgi_app
    response = self.full_dispatch_request()
  File "/home/bc2113451/Desktop/VS Code/Oops/.venv/lib/python3.8/site-packages/flask/app.py", line 1825, in full_dispatch_request
    rv = self.handle_user_exception(e)
  File "/home/bc2113451/Desktop/VS Code/Oops/.venv/lib/python3.8/site-packages/flask/app.py", line 1823, in full_dispatch_request
    rv = self.dispatch_request()
  File "/home/bc2113451/Desktop/VS Code/Oops/.venv/lib/python3.8/site-packages/flask/app.py", line 1799, in dispatch_request
    return self.ensure_sync(self.view_functions[rule.endpoint])(**view_args)
  File "/home/bc2113451/Desktop/VS Code/Oops/Library/settings.py", line 32, in wrapper
    except psycopg2.Error as error:
NameError: name 'psycopg2' is not defined
WARNING :- 2023-04-13 11:04:19,102 - app : Starting the db connection to generate report of books in the list
WARNING :- 2023-04-13 11:04:19,261 - settings : Hence account created, closing the connection
WARNING :- 2023-04-13 11:05:01,820 - app : Starting the db connection to generate report of books in the list
WARNING :- 2023-04-13 11:05:01,950 - settings : Hence account created, closing the connection
WARNING :- 2023-04-13 11:05:43,872 - app : Starting the db connection to generate report of books in the list
WARNING :- 2023-04-13 11:05:44,101 - settings : Hence account created, closing the connection
ERROR :- 2023-04-13 11:05:44,102 - app : Exception on /reviews/Journal [PUT]
Traceback (most recent call last):
  File "/home/bc2113451/Desktop/VS Code/Oops/Library/settings.py", line 31, in wrapper
    return func(*args, **kwargs)
  File "/home/bc2113451/Desktop/VS Code/Oops/Library/app.py", line 217, in add_reviews
    get_username = get_member[0]
TypeError: 'NoneType' object is not subscriptable

During handling of the above exception, another exception occurred:

Traceback (most recent call last):
  File "/home/bc2113451/Desktop/VS Code/Oops/.venv/lib/python3.8/site-packages/flask/app.py", line 2528, in wsgi_app
    response = self.full_dispatch_request()
  File "/home/bc2113451/Desktop/VS Code/Oops/.venv/lib/python3.8/site-packages/flask/app.py", line 1825, in full_dispatch_request
    rv = self.handle_user_exception(e)
  File "/home/bc2113451/Desktop/VS Code/Oops/.venv/lib/python3.8/site-packages/flask/app.py", line 1823, in full_dispatch_request
    rv = self.dispatch_request()
  File "/home/bc2113451/Desktop/VS Code/Oops/.venv/lib/python3.8/site-packages/flask/app.py", line 1799, in dispatch_request
    return self.ensure_sync(self.view_functions[rule.endpoint])(**view_args)
  File "/home/bc2113451/Desktop/VS Code/Oops/Library/settings.py", line 32, in wrapper
    except psycopg2.Error as error:
NameError: name 'psycopg2' is not defined
WARNING :- 2023-04-13 11:06:39,239 - app : Starting the db connection to generate report of books in the list
WARNING :- 2023-04-13 11:06:39,371 - settings : Hence account created, closing the connection
WARNING :- 2023-04-13 11:07:46,401 - app : Starting the db connection to generate report of books in the list
WARNING :- 2023-04-13 11:07:46,576 - settings : Hence account created, closing the connection
WARNING :- 2023-04-13 11:08:38,055 - app : Starting the db connection to generate report of books in the list
WARNING :- 2023-04-13 11:08:38,189 - settings : Hence account created, closing the connection
WARNING :- 2023-04-13 11:10:29,183 - app : Starting the db connection to generate report of books in the list
WARNING :- 2023-04-13 11:10:29,183 - app : Starting the db connection to generate report of books in the list
WARNING :- 2023-04-13 11:10:29,446 - settings : Hence account created, closing the connection
WARNING :- 2023-04-13 11:10:29,446 - settings : Hence account created, closing the connection
WARNING :- 2023-04-13 11:10:46,444 - app : Starting the db connection to generate report of books in the list
WARNING :- 2023-04-13 11:10:46,652 - settings : Hence account created, closing the connection
ERROR :- 2023-04-13 11:10:46,652 - app : Exception on /reviews/1 [PUT]
Traceback (most recent call last):
  File "/home/bc2113451/Desktop/VS Code/Oops/Library/settings.py", line 31, in wrapper
    return func(*args, **kwargs)
  File "/home/bc2113451/Desktop/VS Code/Oops/Library/app.py", line 237, in add_reviews
    return jsonify({"message": data}), 200
NameError: name 'data' is not defined

During handling of the above exception, another exception occurred:

Traceback (most recent call last):
  File "/home/bc2113451/Desktop/VS Code/Oops/.venv/lib/python3.8/site-packages/flask/app.py", line 2528, in wsgi_app
    response = self.full_dispatch_request()
  File "/home/bc2113451/Desktop/VS Code/Oops/.venv/lib/python3.8/site-packages/flask/app.py", line 1825, in full_dispatch_request
    rv = self.handle_user_exception(e)
  File "/home/bc2113451/Desktop/VS Code/Oops/.venv/lib/python3.8/site-packages/flask/app.py", line 1823, in full_dispatch_request
    rv = self.dispatch_request()
  File "/home/bc2113451/Desktop/VS Code/Oops/.venv/lib/python3.8/site-packages/flask/app.py", line 1799, in dispatch_request
    return self.ensure_sync(self.view_functions[rule.endpoint])(**view_args)
  File "/home/bc2113451/Desktop/VS Code/Oops/Library/settings.py", line 32, in wrapper
    except psycopg2.Error as error:
NameError: name 'psycopg2' is not defined
WARNING :- 2023-04-13 11:11:10,059 - app : Starting the db connection to generate report of books in the list
WARNING :- 2023-04-13 11:11:10,247 - settings : Hence account created, closing the connection
WARNING :- 2023-04-13 11:11:44,582 - app : Starting the db connection to generate report of books in the list
WARNING :- 2023-04-13 11:11:44,721 - settings : Hence account created, closing the connection
WARNING :- 2023-04-13 11:12:05,929 - app : Starting the db connection to generate report of books in the list
WARNING :- 2023-04-13 11:12:06,447 - settings : Hence account created, closing the connection
WARNING :- 2023-04-13 11:16:19,972 - app : Starting the db connection to generate report of books in the list
WARNING :- 2023-04-13 11:16:20,117 - settings : Hence account created, closing the connection
WARNING :- 2023-04-13 11:16:25,788 - app : Starting the db connection to generate report of books in the list
WARNING :- 2023-04-13 11:16:25,788 - app : Starting the db connection to generate report of books in the list
WARNING :- 2023-04-13 11:16:25,932 - settings : Hence account created, closing the connection
WARNING :- 2023-04-13 11:16:25,932 - settings : Hence account created, closing the connection
WARNING :- 2023-04-13 11:35:54,229 - app : Starting the db connection to generate report of books in the list
INFO :- 2023-04-13 11:35:54,412 - app : Anjali has been posted a review as Nice novel
INFO :- 2023-04-13 11:35:54,412 - app : Anjali has been posted a review as Nice novel
WARNING :- 2023-04-13 11:35:54,413 - settings : Hence account created, closing the connection
WARNING :- 2023-04-13 11:36:02,363 - app : Starting the db connection to generate report of books in the list
WARNING :- 2023-04-13 11:36:02,363 - app : Starting the db connection to generate report of books in the list
WARNING :- 2023-04-13 11:36:02,363 - app : Starting the db connection to generate report of books in the list
INFO :- 2023-04-13 11:36:02,482 - app : As Kabir has not returned the book so can't post reviews
INFO :- 2023-04-13 11:36:02,482 - app : As Kabir has not returned the book so can't post reviews
INFO :- 2023-04-13 11:36:02,482 - app : As Kabir has not returned the book so can't post reviews
INFO :- 2023-04-13 11:36:02,482 - app : As Kabir has not returned the book so can't post reviews
WARNING :- 2023-04-13 11:36:02,483 - settings : Hence account created, closing the connection
WARNING :- 2023-04-13 11:36:02,483 - settings : Hence account created, closing the connection
WARNING :- 2023-04-13 11:36:43,447 - app : Starting the db connection to generate report of books in the list
WARNING :- 2023-04-13 11:36:43,447 - app : Starting the db connection to generate report of books in the list
WARNING :- 2023-04-13 11:36:43,447 - app : Starting the db connection to generate report of books in the list
WARNING :- 2023-04-13 11:36:43,447 - app : Starting the db connection to generate report of books in the list
WARNING :- 2023-04-13 11:36:43,447 - app : Starting the db connection to generate report of books in the list
INFO :- 2023-04-13 11:36:43,627 - app : Kabir has been posted a review as Perfectly written
INFO :- 2023-04-13 11:36:43,627 - app : Kabir has been posted a review as Perfectly written
INFO :- 2023-04-13 11:36:43,627 - app : Kabir has been posted a review as Perfectly written
INFO :- 2023-04-13 11:36:43,627 - app : Kabir has been posted a review as Perfectly written
INFO :- 2023-04-13 11:36:43,627 - app : Kabir has been posted a review as Perfectly written
INFO :- 2023-04-13 11:36:43,627 - app : Kabir has been posted a review as Perfectly written
WARNING :- 2023-04-13 11:36:43,628 - settings : Hence account created, closing the connection
WARNING :- 2023-04-13 11:36:43,628 - settings : Hence account created, closing the connection
WARNING :- 2023-04-13 11:36:43,628 - settings : Hence account created, closing the connection
WARNING :- 2023-04-13 11:56:56,241 - app : Starting the db connection to add user's request in the list
INFO :- 2023-04-13 11:56:56,459 - app : Anjali has been posted requests of Wings of Fire
INFO :- 2023-04-13 11:56:56,459 - app : Anjali has been posted requests of Wings of Fire
WARNING :- 2023-04-13 11:56:56,460 - settings : Hence account created, closing the connection
WARNING :- 2023-04-13 12:08:44,418 - app : Starting the db connection to calculate the user's fine if not returned
WARNING :- 2023-04-13 12:08:44,579 - settings : Closing the connection
ERROR :- 2023-04-13 12:08:44,579 - app : Exception on /fine_calc/2 [PUT]
Traceback (most recent call last):
  File "/home/bc2113451/Desktop/VS Code/Oops/.venv/lib/python3.8/site-packages/flask/wrappers.py", line 128, in on_json_loading_failed
    return super().on_json_loading_failed(e)
  File "/home/bc2113451/Desktop/VS Code/Oops/.venv/lib/python3.8/site-packages/werkzeug/wrappers/request.py", line 631, in on_json_loading_failed
    raise BadRequest(
werkzeug.exceptions.BadRequest: 400 Bad Request: Did not attempt to load JSON data because the request Content-Type was not 'application/json'.

The above exception was the direct cause of the following exception:

Traceback (most recent call last):
  File "/home/bc2113451/Desktop/VS Code/Oops/Library/settings.py", line 31, in wrapper
    return func(*args, **kwargs)
  File "/home/bc2113451/Desktop/VS Code/Oops/Library/app.py", line 327, in fine_calculations
    data = request.get_json()
  File "/home/bc2113451/Desktop/VS Code/Oops/.venv/lib/python3.8/site-packages/werkzeug/wrappers/request.py", line 591, in get_json
    return self.on_json_loading_failed(None)
  File "/home/bc2113451/Desktop/VS Code/Oops/.venv/lib/python3.8/site-packages/flask/wrappers.py", line 133, in on_json_loading_failed
    raise BadRequest() from e
werkzeug.exceptions.BadRequest: 400 Bad Request: The browser (or proxy) sent a request that this server could not understand.

During handling of the above exception, another exception occurred:

Traceback (most recent call last):
  File "/home/bc2113451/Desktop/VS Code/Oops/.venv/lib/python3.8/site-packages/flask/app.py", line 2528, in wsgi_app
    response = self.full_dispatch_request()
  File "/home/bc2113451/Desktop/VS Code/Oops/.venv/lib/python3.8/site-packages/flask/app.py", line 1825, in full_dispatch_request
    rv = self.handle_user_exception(e)
  File "/home/bc2113451/Desktop/VS Code/Oops/.venv/lib/python3.8/site-packages/flask/app.py", line 1823, in full_dispatch_request
    rv = self.dispatch_request()
  File "/home/bc2113451/Desktop/VS Code/Oops/.venv/lib/python3.8/site-packages/flask/app.py", line 1799, in dispatch_request
    return self.ensure_sync(self.view_functions[rule.endpoint])(**view_args)
  File "/home/bc2113451/Desktop/VS Code/Oops/Library/settings.py", line 32, in wrapper
    except psycopg2.Error as error:
NameError: name 'psycopg2' is not defined
WARNING :- 2023-04-13 12:09:20,741 - app : Starting the db connection to calculate the user's fine if not returned
WARNING :- 2023-04-13 12:09:20,897 - settings : Closing the connection
ERROR :- 2023-04-13 12:09:20,898 - app : Exception on /fine_calc/2 [PUT]
Traceback (most recent call last):
  File "/home/bc2113451/Desktop/VS Code/Oops/.venv/lib/python3.8/site-packages/flask/wrappers.py", line 128, in on_json_loading_failed
    return super().on_json_loading_failed(e)
  File "/home/bc2113451/Desktop/VS Code/Oops/.venv/lib/python3.8/site-packages/werkzeug/wrappers/request.py", line 631, in on_json_loading_failed
    raise BadRequest(
werkzeug.exceptions.BadRequest: 400 Bad Request: Did not attempt to load JSON data because the request Content-Type was not 'application/json'.

The above exception was the direct cause of the following exception:

Traceback (most recent call last):
  File "/home/bc2113451/Desktop/VS Code/Oops/Library/settings.py", line 31, in wrapper
    return func(*args, **kwargs)
  File "/home/bc2113451/Desktop/VS Code/Oops/Library/app.py", line 327, in fine_calculations
    data = request.get_json()
  File "/home/bc2113451/Desktop/VS Code/Oops/.venv/lib/python3.8/site-packages/werkzeug/wrappers/request.py", line 591, in get_json
    return self.on_json_loading_failed(None)
  File "/home/bc2113451/Desktop/VS Code/Oops/.venv/lib/python3.8/site-packages/flask/wrappers.py", line 133, in on_json_loading_failed
    raise BadRequest() from e
werkzeug.exceptions.BadRequest: 400 Bad Request: The browser (or proxy) sent a request that this server could not understand.

During handling of the above exception, another exception occurred:

Traceback (most recent call last):
  File "/home/bc2113451/Desktop/VS Code/Oops/.venv/lib/python3.8/site-packages/flask/app.py", line 2528, in wsgi_app
    response = self.full_dispatch_request()
  File "/home/bc2113451/Desktop/VS Code/Oops/.venv/lib/python3.8/site-packages/flask/app.py", line 1825, in full_dispatch_request
    rv = self.handle_user_exception(e)
  File "/home/bc2113451/Desktop/VS Code/Oops/.venv/lib/python3.8/site-packages/flask/app.py", line 1823, in full_dispatch_request
    rv = self.dispatch_request()
  File "/home/bc2113451/Desktop/VS Code/Oops/.venv/lib/python3.8/site-packages/flask/app.py", line 1799, in dispatch_request
    return self.ensure_sync(self.view_functions[rule.endpoint])(**view_args)
  File "/home/bc2113451/Desktop/VS Code/Oops/Library/settings.py", line 32, in wrapper
    except psycopg2.Error as error:
NameError: name 'psycopg2' is not defined
WARNING :- 2023-04-13 12:10:18,429 - app : Starting the db connection to calculate the user's fine if not returned
WARNING :- 2023-04-13 12:10:18,583 - settings : Closing the connection
ERROR :- 2023-04-13 12:10:18,583 - app : Exception on /fine_calc/2 [PUT]
Traceback (most recent call last):
  File "/home/bc2113451/Desktop/VS Code/Oops/.venv/lib/python3.8/site-packages/flask/wrappers.py", line 128, in on_json_loading_failed
    return super().on_json_loading_failed(e)
  File "/home/bc2113451/Desktop/VS Code/Oops/.venv/lib/python3.8/site-packages/werkzeug/wrappers/request.py", line 631, in on_json_loading_failed
    raise BadRequest(
werkzeug.exceptions.BadRequest: 400 Bad Request: Did not attempt to load JSON data because the request Content-Type was not 'application/json'.

The above exception was the direct cause of the following exception:

Traceback (most recent call last):
  File "/home/bc2113451/Desktop/VS Code/Oops/Library/settings.py", line 31, in wrapper
    return func(*args, **kwargs)
  File "/home/bc2113451/Desktop/VS Code/Oops/Library/app.py", line 327, in fine_calculations
    fine = request.json('fine')
  File "/home/bc2113451/Desktop/VS Code/Oops/.venv/lib/python3.8/site-packages/werkzeug/wrappers/request.py", line 548, in json
    return self.get_json()
  File "/home/bc2113451/Desktop/VS Code/Oops/.venv/lib/python3.8/site-packages/werkzeug/wrappers/request.py", line 591, in get_json
    return self.on_json_loading_failed(None)
  File "/home/bc2113451/Desktop/VS Code/Oops/.venv/lib/python3.8/site-packages/flask/wrappers.py", line 133, in on_json_loading_failed
    raise BadRequest() from e
werkzeug.exceptions.BadRequest: 400 Bad Request: The browser (or proxy) sent a request that this server could not understand.

During handling of the above exception, another exception occurred:

Traceback (most recent call last):
  File "/home/bc2113451/Desktop/VS Code/Oops/.venv/lib/python3.8/site-packages/flask/app.py", line 2528, in wsgi_app
    response = self.full_dispatch_request()
  File "/home/bc2113451/Desktop/VS Code/Oops/.venv/lib/python3.8/site-packages/flask/app.py", line 1825, in full_dispatch_request
    rv = self.handle_user_exception(e)
  File "/home/bc2113451/Desktop/VS Code/Oops/.venv/lib/python3.8/site-packages/flask/app.py", line 1823, in full_dispatch_request
    rv = self.dispatch_request()
  File "/home/bc2113451/Desktop/VS Code/Oops/.venv/lib/python3.8/site-packages/flask/app.py", line 1799, in dispatch_request
    return self.ensure_sync(self.view_functions[rule.endpoint])(**view_args)
  File "/home/bc2113451/Desktop/VS Code/Oops/Library/settings.py", line 32, in wrapper
    except psycopg2.Error as error:
NameError: name 'psycopg2' is not defined
WARNING :- 2023-04-13 12:12:55,143 - app : Starting the db connection to calculate the user's fine if not returned
WARNING :- 2023-04-13 12:12:55,262 - settings : Closing the connection
WARNING :- 2023-04-13 12:13:16,258 - app : Starting the db connection to calculate the user's fine if not returned
WARNING :- 2023-04-13 12:13:16,258 - app : Starting the db connection to calculate the user's fine if not returned
INFO :- 2023-04-13 12:13:16,465 - app : Kabir has borrowed on 2022-09-12 and not yet returned the book, so the fine is 200
INFO :- 2023-04-13 12:13:16,465 - app : Kabir has borrowed on 2022-09-12 and not yet returned the book, so the fine is 200
INFO :- 2023-04-13 12:13:16,465 - app : Kabir has borrowed on 2022-09-12 and not yet returned the book, so the fine is 200
WARNING :- 2023-04-13 12:13:16,466 - settings : Closing the connection
WARNING :- 2023-04-13 12:13:16,466 - settings : Closing the connection
WARNING :- 2023-04-13 12:14:03,829 - app : Starting the db connection to calculate the user's fine if not returned
INFO :- 2023-04-13 12:14:04,044 - app : Kabir has borrowed book on 2022-09-12 and not yet returned it, so the fine is 200
INFO :- 2023-04-13 12:14:04,044 - app : Kabir has borrowed book on 2022-09-12 and not yet returned it, so the fine is 200
WARNING :- 2023-04-13 12:14:04,045 - settings : Closing the connection
WARNING :- 2023-04-13 12:14:13,596 - app : Starting the db connection to calculate the user's fine if not returned
WARNING :- 2023-04-13 12:14:13,596 - app : Starting the db connection to calculate the user's fine if not returned
WARNING :- 2023-04-13 12:14:13,596 - app : Starting the db connection to calculate the user's fine if not returned
WARNING :- 2023-04-13 12:14:13,724 - settings : Closing the connection
WARNING :- 2023-04-13 12:14:13,724 - settings : Closing the connection
WARNING :- 2023-04-13 12:15:06,891 - app : Starting the db connection to calculate the user's fine if not returned
WARNING :- 2023-04-13 12:15:07,082 - settings : Closing the connection
WARNING :- 2023-04-13 12:15:11,269 - app : Starting the db connection to calculate the user's fine if not returned
WARNING :- 2023-04-13 12:15:11,269 - app : Starting the db connection to calculate the user's fine if not returned
WARNING :- 2023-04-13 12:15:11,445 - settings : Closing the connection
WARNING :- 2023-04-13 12:15:11,445 - settings : Closing the connection
